<?xml version="1.0"?>
<robot name="wheeltec">
  <link name="base_link">
    <inertial>
      <mass value="0.6"/>
      <inertia ixx="0.0018" ixy="0" ixz="0" iyy="0.0036" iyz="0" izz="0.0048"/>
    </inertial>
    <visual>
      <origin xyz="0 0 0.07" rpy="0 0 0"/>
      <geometry>
        <mesh filename="file:///home/josh/ros2_ws/src/wheeltec_description/meshes/mini_4wd/base_link.STL"/>
      </geometry>
      <material name="grey"/>
    </visual>
    <collision>
      <origin xyz="0 0 0.07" rpy="0 0 0"/>
      <geometry>
        <mesh filename="file:///home/josh/ros2_ws/src/wheeltec_description/meshes/mini_4wd/base_link.STL"/>
      </geometry>
    </collision>
  </link>

  <link name="right_front_wheel_link">
    <inertial>
      <mass value="0.053774"/>
      <inertia ixx="0.00001996" ixy="-0.000000000000014777" ixz="0.000000000068928" iyy="0.000034111" iyz="-0.0000000000018473" izz="0.00001996"/>
    </inertial>
    <visual>
      <origin xyz="0 0 0" rpy="0 0 0"/>
      <geometry>
        <mesh filename="file:///home/josh/ros2_ws/src/wheeltec_description/meshes/mini_4wd/right_front_wheel_link.STL"/>
      </geometry>
      <material name="black"/>
    </visual>
    <collision>
      <origin xyz="0 0 0" rpy="0 0 0"/>
      <geometry>
        <mesh filename="file:///home/josh/ros2_ws/src/wheeltec_description/meshes/mini_4wd/right_front_wheel_link.STL"/>
      </geometry>
    </collision>
  </link>
  <joint name="right_front_wheel_joint" type="continuous">
    <parent link="base_link"/>
    <child link="right_front_wheel_link"/>
    <origin xyz="0.0725 -0.08661 -0.026385" rpy="0 0 0"/>
    <axis xyz="0 1 0"/>
  </joint>

  <!-- Add similar entries for left_front, right_rear, left_rear wheels -->
</robot>